(dp1
S'output'
p2
S'<type \'exceptions.RuntimeError\'> Failure to connect, tried 5 times:\nTraceback (most recent call last):\n  File "/Users/Ran/PycharmProjects/untitled/web2py/gluon/packages/dal/pydal/base.py", line 457, in __init__\n    self._adapter = adapter(**kwargs)\n  File "/Users/Ran/PycharmProjects/untitled/web2py/gluon/packages/dal/pydal/adapters/postgres.py", line 27, in __call__\n    return AdapterMeta.__call__(cls, *args, **kwargs)\n  File "/Users/Ran/PycharmProjects/untitled/web2py/gluon/packages/dal/pydal/adapters/__init__.py", line 39, in __call__\n    obj = super(AdapterMeta, cls).__call__(*args, **kwargs)\n  File "/Users/Ran/PycharmProjects/untitled/web2py/gluon/packages/dal/pydal/adapters/postgres.py", line 54, in __init__\n    driver_args, adapter_args, do_connect, after_connection)\n  File "/Users/Ran/PycharmProjects/untitled/web2py/gluon/packages/dal/pydal/adapters/base.py", line 369, in __init__\n    super(SQLAdapter, self).__init__(*args, **kwargs)\n  File "/Users/Ran/PycharmProjects/untitled/web2py/gluon/packages/dal/pydal/adapters/base.py", line 50, in __init__\n    self.find_driver()\n  File "/Users/Ran/PycharmProjects/untitled/web2py/gluon/packages/dal/pydal/adapters/base.py", line 101, in find_driver\n    str(self.drivers))\nRuntimeError: No driver of supported ones (\'psycopg2\',) is available\n'
p3
sS'layer'
p4
S'/Users/Ran/PycharmProjects/untitled/web2py/applications/shotsapp/controllers/shots.py'
p5
sS'code'
p6
S'<code object <module> at 0x10cc5d530, file "/Users/Ran/PycharmProjects/untitled/web2py/applications/shotsapp/controllers/shots.py", line 4>'
p7
sS'snapshot'
p8
(dp9
sS'traceback'
p10
S'Traceback (most recent call last):\n  File "/Users/Ran/PycharmProjects/untitled/web2py/gluon/restricted.py", line 219, in restricted\n    exec(ccode, environment)\n  File "/Users/Ran/PycharmProjects/untitled/web2py/applications/shotsapp/controllers/shots.py", line 6, in <module>\n    db = DAL(\'postgres://aotqayomrrkmvj:2f76887817375959a665e0de6cfa5e7d480379f9014c9c615cd4bbe78f4d1e2e@ec2-46-137-113-157.eu-west-1.compute.amazonaws.com:5432/d4ctt3ajqhrsgt\')\n  File "/Users/Ran/PycharmProjects/untitled/web2py/gluon/packages/dal/pydal/base.py", line 171, in __call__\n    obj = super(MetaDAL, cls).__call__(*args, **kwargs)\n  File "/Users/Ran/PycharmProjects/untitled/web2py/gluon/packages/dal/pydal/base.py", line 477, in __init__\n    "Failure to connect, tried %d times:\\n%s" % (attempts, tb)\nRuntimeError: Failure to connect, tried 5 times:\nTraceback (most recent call last):\n  File "/Users/Ran/PycharmProjects/untitled/web2py/gluon/packages/dal/pydal/base.py", line 457, in __init__\n    self._adapter = adapter(**kwargs)\n  File "/Users/Ran/PycharmProjects/untitled/web2py/gluon/packages/dal/pydal/adapters/postgres.py", line 27, in __call__\n    return AdapterMeta.__call__(cls, *args, **kwargs)\n  File "/Users/Ran/PycharmProjects/untitled/web2py/gluon/packages/dal/pydal/adapters/__init__.py", line 39, in __call__\n    obj = super(AdapterMeta, cls).__call__(*args, **kwargs)\n  File "/Users/Ran/PycharmProjects/untitled/web2py/gluon/packages/dal/pydal/adapters/postgres.py", line 54, in __init__\n    driver_args, adapter_args, do_connect, after_connection)\n  File "/Users/Ran/PycharmProjects/untitled/web2py/gluon/packages/dal/pydal/adapters/base.py", line 369, in __init__\n    super(SQLAdapter, self).__init__(*args, **kwargs)\n  File "/Users/Ran/PycharmProjects/untitled/web2py/gluon/packages/dal/pydal/adapters/base.py", line 50, in __init__\n    self.find_driver()\n  File "/Users/Ran/PycharmProjects/untitled/web2py/gluon/packages/dal/pydal/adapters/base.py", line 101, in find_driver\n    str(self.drivers))\nRuntimeError: No driver of supported ones (\'psycopg2\',) is available\n\n'
p11
s.