(dp1
S'output'
p2
S'<type \'exceptions.RuntimeError\'> Failure to connect, tried 5 times:\nTraceback (most recent call last):\n  File "/Users/Ran/PycharmProjects/untitled/web2py/gluon/packages/dal/pydal/base.py", line 457, in __init__\n    self._adapter = adapter(**kwargs)\n  File "/Users/Ran/PycharmProjects/untitled/web2py/gluon/packages/dal/pydal/adapters/__init__.py", line 39, in __call__\n    obj = super(AdapterMeta, cls).__call__(*args, **kwargs)\n  File "/Users/Ran/PycharmProjects/untitled/web2py/gluon/packages/dal/pydal/adapters/base.py", line 369, in __init__\n    super(SQLAdapter, self).__init__(*args, **kwargs)\n  File "/Users/Ran/PycharmProjects/untitled/web2py/gluon/packages/dal/pydal/adapters/base.py", line 53, in __init__\n    self.reconnect()\n  File "/Users/Ran/PycharmProjects/untitled/web2py/gluon/packages/dal/pydal/connection.py", line 154, in reconnect\n    self.connection = self.connector()\n  File "/Users/Ran/PycharmProjects/untitled/web2py/gluon/packages/dal/pydal/adapters/mysql.py", line 51, in connector\n    return self.driver.connect(**self.driver_args)\n  File "/Users/Ran/PycharmProjects/untitled/web2py/gluon/contrib/pymysql/__init__.py", line 90, in Connect\n    return Connection(*args, **kwargs)\n  File "/Users/Ran/PycharmProjects/untitled/web2py/gluon/contrib/pymysql/connections.py", line 688, in __init__\n    self.connect()\n  File "/Users/Ran/PycharmProjects/untitled/web2py/gluon/contrib/pymysql/connections.py", line 906, in connect\n    self._request_authentication()\n  File "/Users/Ran/PycharmProjects/untitled/web2py/gluon/contrib/pymysql/connections.py", line 1114, in _request_authentication\n    auth_packet = self._read_packet()\n  File "/Users/Ran/PycharmProjects/untitled/web2py/gluon/contrib/pymysql/connections.py", line 981, in _read_packet\n    packet.check_error()\n  File "/Users/Ran/PycharmProjects/untitled/web2py/gluon/contrib/pymysql/connections.py", line 393, in check_error\n    err.raise_mysql_exception(self._data)\n  File "/Users/Ran/PycharmProjects/untitled/web2py/gluon/contrib/pymysql/err.py", line 107, in raise_mysql_exception\n    raise errorclass(errno, errval)\nOperationalError: (1045, u"Access denied for user \'o51wuugoaddp2s62\'@\'141.226.10.33\' (using password: YES)")\n'
p3
sS'layer'
p4
S'/Users/Ran/PycharmProjects/untitled/web2py/applications/shotsapp/controllers/shots.py'
p5
sS'code'
p6
S'<code object <module> at 0x10800b8b0, file "/Users/Ran/PycharmProjects/untitled/web2py/applications/shotsapp/controllers/shots.py", line 4>'
p7
sS'snapshot'
p8
(dp9
sS'traceback'
p10
S'Traceback (most recent call last):\n  File "/Users/Ran/PycharmProjects/untitled/web2py/gluon/restricted.py", line 219, in restricted\n    exec(ccode, environment)\n  File "/Users/Ran/PycharmProjects/untitled/web2py/applications/shotsapp/controllers/shots.py", line 6, in <module>\n    db = DAL(\'mysql://o51wuugoaddp2s62:dl1vy2ps42znltfd@w1kr9ijlozl9l79i.chr7pe7iynqr.eu-west-1.rds.amazonaws.com:3306/binjo6x0bhaoabnu\')\n  File "/Users/Ran/PycharmProjects/untitled/web2py/gluon/packages/dal/pydal/base.py", line 171, in __call__\n    obj = super(MetaDAL, cls).__call__(*args, **kwargs)\n  File "/Users/Ran/PycharmProjects/untitled/web2py/gluon/packages/dal/pydal/base.py", line 477, in __init__\n    "Failure to connect, tried %d times:\\n%s" % (attempts, tb)\nRuntimeError: Failure to connect, tried 5 times:\nTraceback (most recent call last):\n  File "/Users/Ran/PycharmProjects/untitled/web2py/gluon/packages/dal/pydal/base.py", line 457, in __init__\n    self._adapter = adapter(**kwargs)\n  File "/Users/Ran/PycharmProjects/untitled/web2py/gluon/packages/dal/pydal/adapters/__init__.py", line 39, in __call__\n    obj = super(AdapterMeta, cls).__call__(*args, **kwargs)\n  File "/Users/Ran/PycharmProjects/untitled/web2py/gluon/packages/dal/pydal/adapters/base.py", line 369, in __init__\n    super(SQLAdapter, self).__init__(*args, **kwargs)\n  File "/Users/Ran/PycharmProjects/untitled/web2py/gluon/packages/dal/pydal/adapters/base.py", line 53, in __init__\n    self.reconnect()\n  File "/Users/Ran/PycharmProjects/untitled/web2py/gluon/packages/dal/pydal/connection.py", line 154, in reconnect\n    self.connection = self.connector()\n  File "/Users/Ran/PycharmProjects/untitled/web2py/gluon/packages/dal/pydal/adapters/mysql.py", line 51, in connector\n    return self.driver.connect(**self.driver_args)\n  File "/Users/Ran/PycharmProjects/untitled/web2py/gluon/contrib/pymysql/__init__.py", line 90, in Connect\n    return Connection(*args, **kwargs)\n  File "/Users/Ran/PycharmProjects/untitled/web2py/gluon/contrib/pymysql/connections.py", line 688, in __init__\n    self.connect()\n  File "/Users/Ran/PycharmProjects/untitled/web2py/gluon/contrib/pymysql/connections.py", line 906, in connect\n    self._request_authentication()\n  File "/Users/Ran/PycharmProjects/untitled/web2py/gluon/contrib/pymysql/connections.py", line 1114, in _request_authentication\n    auth_packet = self._read_packet()\n  File "/Users/Ran/PycharmProjects/untitled/web2py/gluon/contrib/pymysql/connections.py", line 981, in _read_packet\n    packet.check_error()\n  File "/Users/Ran/PycharmProjects/untitled/web2py/gluon/contrib/pymysql/connections.py", line 393, in check_error\n    err.raise_mysql_exception(self._data)\n  File "/Users/Ran/PycharmProjects/untitled/web2py/gluon/contrib/pymysql/err.py", line 107, in raise_mysql_exception\n    raise errorclass(errno, errval)\nOperationalError: (1045, u"Access denied for user \'o51wuugoaddp2s62\'@\'141.226.10.33\' (using password: YES)")\n\n'
p11
s.